/*
    const myFunction = async () => {
        try {
            let result = await promist
        } catch( error) {            //if have nothing work not correctly catch will be auto run
            console.log(error)
        }
    }
*/